[2023-12-07T23:56:20.879+0000] {taskinstance.py:1159} INFO - Dependencies all met for dep_context=non-requeueable deps ti=<TaskInstance: sandbox.segmentation manual__2023-12-07T23:56:07.220028+00:00 [queued]>
[2023-12-07T23:56:20.887+0000] {taskinstance.py:1159} INFO - Dependencies all met for dep_context=requeueable deps ti=<TaskInstance: sandbox.segmentation manual__2023-12-07T23:56:07.220028+00:00 [queued]>
[2023-12-07T23:56:20.888+0000] {taskinstance.py:1361} INFO - Starting attempt 1 of 1
[2023-12-07T23:56:20.898+0000] {taskinstance.py:1382} INFO - Executing <Task(PythonOperator): segmentation> on 2023-12-07 23:56:07.220028+00:00
[2023-12-07T23:56:20.908+0000] {standard_task_runner.py:57} INFO - Started process 221 to run task
[2023-12-07T23:56:20.916+0000] {standard_task_runner.py:84} INFO - Running: ['***', 'tasks', 'run', 'sandbox', 'segmentation', 'manual__2023-12-07T23:56:07.220028+00:00', '--job-id', '52', '--raw', '--subdir', 'DAGS_FOLDER/sandbox.py', '--cfg-path', '/tmp/tmpsk0cvb4f']
[2023-12-07T23:56:20.926+0000] {standard_task_runner.py:85} INFO - Job 52: Subtask segmentation
[2023-12-07T23:56:21.011+0000] {task_command.py:416} INFO - Running <TaskInstance: sandbox.segmentation manual__2023-12-07T23:56:07.220028+00:00 [running]> on host 93a86e24e563
[2023-12-07T23:56:21.099+0000] {taskinstance.py:1662} INFO - Exporting env vars: AIRFLOW_CTX_DAG_OWNER='***' AIRFLOW_CTX_DAG_ID='sandbox' AIRFLOW_CTX_TASK_ID='segmentation' AIRFLOW_CTX_EXECUTION_DATE='2023-12-07T23:56:07.220028+00:00' AIRFLOW_CTX_TRY_NUMBER='1' AIRFLOW_CTX_DAG_RUN_ID='manual__2023-12-07T23:56:07.220028+00:00'
[2023-12-07T23:56:21.103+0000] {taskinstance.py:1937} ERROR - Task failed with exception
Traceback (most recent call last):
  File "/home/airflow/.local/lib/python3.8/site-packages/airflow/operators/python.py", line 192, in execute
    return_value = self.execute_callable()
  File "/home/airflow/.local/lib/python3.8/site-packages/airflow/operators/python.py", line 209, in execute_callable
    return self.python_callable(*self.op_args, **self.op_kwargs)
  File "/opt/airflow/dags/sandbox.py", line 103, in segmentation
    original_dict = data_scraping()
TypeError: 'PythonOperator' object is not callable
[2023-12-07T23:56:21.117+0000] {taskinstance.py:1400} INFO - Marking task as FAILED. dag_id=sandbox, task_id=segmentation, execution_date=20231207T235607, start_date=20231207T235620, end_date=20231207T235621
[2023-12-07T23:56:21.130+0000] {standard_task_runner.py:104} ERROR - Failed to execute job 52 for task segmentation ('PythonOperator' object is not callable; 221)
[2023-12-07T23:56:21.169+0000] {local_task_job_runner.py:228} INFO - Task exited with return code 1
[2023-12-07T23:56:21.197+0000] {taskinstance.py:2778} INFO - 0 downstream tasks scheduled from follow-on schedule check
